<?xml version="1.0" encoding="utf-8"?>
<!--
  SO-ARM101 MuJoCo MJCF Model
  ════════════════════════════
  6-DOF low-cost robot arm approximation based on SO-ARM101 specs.

  Joints:
    joint1_rotation   — base rotation  (Z-axis, ±180°)
    joint2_pitch      — shoulder pitch  (Y-axis, ±90°)
    joint3_elbow      — elbow pitch     (Y-axis, ±150°)
    joint4_wrist_pitch— wrist pitch     (Y-axis, ±90°)
    joint5_wrist_roll — wrist roll      (Z-axis, ±180°)
    gripper_left/right— parallel gripper (0–25mm each)

  Actuators: position-controlled (PD) with kp gains
  Sensors:   TCP position + quaternion via site "end_effector"
-->
<mujoco model="so_arm101">
  <compiler angle="radian" coordinate="local"/>
  <option gravity="0 0 -9.81" timestep="0.002"/>

  <default>
    <joint limited="true" damping="0.5" armature="0.01"/>
    <geom contype="1" conaffinity="1" friction="1 0.005 0.0001"/>
  </default>

  <asset>
    <material name="metal"   rgba="0.65 0.65 0.70 1"/>
    <material name="joint"   rgba="0.25 0.45 0.85 1"/>
    <material name="gripper" rgba="0.90 0.60 0.20 1"/>
    <material name="floor"   rgba="0.85 0.85 0.85 1"/>
  </asset>

  <worldbody>
    <light pos="0 0 3"   dir="0 0 -1"   diffuse="0.8 0.8 0.8"/>
    <light pos="1 1 1.5" dir="-1 -1 -1" diffuse="0.4 0.4 0.4"/>
    <geom name="floor" type="plane" size="1 1 0.1" material="floor" pos="0 0 -0.01"/>

    <!-- ── Base ──────────────────────────────────────────────────── -->
    <body name="base" pos="0 0 0">
      <geom name="base_col"  type="cylinder" size="0.07 0.045" material="metal" pos="0 0 0.045"/>
      <geom name="base_ring" type="cylinder" size="0.08 0.005" material="joint" pos="0 0 0.088"/>
      <inertial pos="0 0 0.045" mass="0.6" diaginertia="0.002 0.002 0.002"/>

      <!-- ── Joint 1: Base Rotation (Z) ────────────────────────── -->
      <body name="link1" pos="0 0 0.095">
        <joint name="joint1_rotation" type="hinge" axis="0 0 1" range="-3.14159 3.14159"/>
        <geom name="j1_body" type="cylinder" size="0.045 0.055" material="metal"  pos="0 0 0.055"/>
        <geom name="j1_ring" type="cylinder" size="0.048 0.004" material="joint"  pos="0 0 0.108"/>
        <inertial pos="0 0 0.055" mass="0.32" diaginertia="0.0006 0.0006 0.0003"/>

        <!-- ── Joint 2: Shoulder Pitch (Y) ───────────────────────── -->
        <body name="link2" pos="0 0 0.115">
          <joint name="joint2_pitch" type="hinge" axis="0 1 0" range="-1.5708 1.5708"/>
          <geom name="j2_cap" type="capsule" size="0.032" fromto="0 0 0 0 0 0.140" material="metal"/>
          <inertial pos="0 0 0.070" mass="0.26" diaginertia="0.0004 0.0004 0.0001"/>

          <!-- ── Joint 3: Elbow Pitch (Y) ────────────────────────── -->
          <body name="link3" pos="0 0 0.140">
            <joint name="joint3_elbow" type="hinge" axis="0 1 0" range="-2.618 2.618"/>
            <geom name="j3_cap" type="capsule" size="0.026" fromto="0 0 0 0 0 0.120" material="metal"/>
            <inertial pos="0 0 0.060" mass="0.21" diaginertia="0.0003 0.0003 0.0001"/>

            <!-- ── Joint 4: Wrist Pitch (Y) ──────────────────────── -->
            <body name="link4" pos="0 0 0.120">
              <joint name="joint4_wrist_pitch" type="hinge" axis="0 1 0" range="-1.5708 1.5708"/>
              <geom name="j4_cap" type="capsule" size="0.020" fromto="0 0 0 0 0 0.085" material="metal"/>
              <inertial pos="0 0 0.042" mass="0.15" diaginertia="0.0001 0.0001 0.00005"/>

              <!-- ── Joint 5: Wrist Roll (Z) ────────────────────── -->
              <body name="link5" pos="0 0 0.085">
                <joint name="joint5_wrist_roll" type="hinge" axis="0 0 1" range="-3.14159 3.14159"/>
                <geom name="j5_body" type="cylinder" size="0.018 0.028" material="joint" pos="0 0 0.028"/>
                <inertial pos="0 0 0.028" mass="0.10" diaginertia="0.00005 0.00005 0.00003"/>

                <!-- ── Gripper ───────────────────────────────────── -->
                <body name="gripper_base" pos="0 0 0.060">
                  <geom name="grip_body" type="box" size="0.030 0.020 0.018" material="gripper" pos="0 0 0.010"/>
                  <inertial pos="0 0 0.010" mass="0.09" diaginertia="0.00003 0.00003 0.00002"/>

                  <body name="finger_left" pos="-0.022 0 0.030">
                    <joint name="gripper_left" type="slide" axis="-1 0 0" range="0 0.025"/>
                    <geom type="box" size="0.008 0.011 0.022" material="gripper" pos="0 0 0.013"/>
                    <inertial pos="0 0 0.013" mass="0.020" diaginertia="0.000005 0.000005 0.000002"/>
                  </body>

                  <body name="finger_right" pos="0.022 0 0.030">
                    <joint name="gripper_right" type="slide" axis="1 0 0" range="0 0.025"/>
                    <geom type="box" size="0.008 0.011 0.022" material="gripper" pos="0 0 0.013"/>
                    <inertial pos="0 0 0.013" mass="0.020" diaginertia="0.000005 0.000005 0.000002"/>
                  </body>

                  <!-- TCP: Tool Center Point -->
                  <site name="end_effector" pos="0 0 0.080" size="0.012" rgba="1 0 0 0.8"/>
                </body>
              </body>
            </body>
          </body>
        </body>
      </body>
    </body>
  </worldbody>

  <!-- ── Position-controlled actuators ──────────────────────────────── -->
  <actuator>
    <position name="act_j1" joint="joint1_rotation"   kp="60" gear="1"/>
    <position name="act_j2" joint="joint2_pitch"       kp="60" gear="1"/>
    <position name="act_j3" joint="joint3_elbow"       kp="60" gear="1"/>
    <position name="act_j4" joint="joint4_wrist_pitch" kp="40" gear="1"/>
    <position name="act_j5" joint="joint5_wrist_roll"  kp="30" gear="1"/>
    <position name="act_gl" joint="gripper_left"        kp="25" gear="1"/>
    <position name="act_gr" joint="gripper_right"       kp="25" gear="1"/>
  </actuator>

  <!-- ── Sensors ────────────────────────────────────────────────────── -->
  <sensor>
    <framepos  name="tcp_pos"  objtype="site" objname="end_effector"/>
    <framequat name="tcp_quat" objtype="site" objname="end_effector"/>
  </sensor>

</mujoco>
